Workbook

Sheet README
A1: شات بوت العربيات — دليل تعبئة الداتا
A2: الهدف | B2: الشيتين Cars و Faults هما مصدر المعلومات الوحيد للبوت. أي معلومة مش موجودة هنا البوت مش هيعرفها.
A4: قواعد لازم الكل يلتزم بيها
A5: 1. صف واحد = عربية واحدة / عطل واحد | B5: لو نفس الموديل بسنتين مختلفتين أو سعرين، اكتبهم في صفين.
A6: 2. الأرقام أرقام بس | B6: السعر 1050000 (بدون فواصل أو 'جنيه')، السنة 2022، السي سي 1600. الفلترة بالسعر بتعتمد على كده.
A7: 3. القوائم المنسدلة | B7: الأعمدة اللي فيها سهم (الحالة، الناقل، الوقود، نعم/لا، الفئة، الخطورة) اختار من القائمة ومتكتبش بإيدك، عشان البوت يفهم القيم موحدة.
A8: 4. الأعمدة الرمادية تلقائية | B8: Car_ID / Brand_AR / Data_Check / Search_Text متلمسهاش. Brand_AR بيتكتب لوحده من اسم البراند.
A9: 5. لا تغير أسماء العناوين | B9: الكود بيقرأ الأعمدة بأسمائها الإنجليزي (صف 1). ممنوع تغيير الاسم أو تدمج خلايا أو تضيف صفوف فاضية فوق الداتا.
A10: 6. ماتمسحش صفوف | B10: لو عايز تمسح بيانات امسح محتوى الخلايا بس (Delete) من غير ما تمسح الصف نفسه.
A11: 7. عمود Data_Check | B11: لازم يبقى أخضر OK. أحمر = في خانة مطلوبة ناقصة أو رقم مكتوب غلط.
A12: 8. الداتا المبدئية | B12: Cars: 44 صف، الأسعار من قائمة أكتوبر 2026 (banker.news) وبتتغير باستمرار فراجعوها مع الوكيل قبل العرض. الخانات الفاضية (الحصان، الاستهلاك، الإمكانيات) للتيم يستكملها من ContactCars / Hatla2ee / موقع الوكيل. Faults: 56 عطل، والتكاليف تقديرية بس.
A13: 9. الفاضي = غير معروف | B13: خانة فاضية معناها المعلومة لسه متتأكدش منها، مش إن الميزة مش موجودة. اكتبوا نعم أو لا بس لما تتأكدوا.
A15: شيت Cars — الأعمدة
A16: Brand / Model | B16: الاسم بالإنجليزي (Toyota / Corolla). Brand بيتختار من قائمة.
A17: Model_AR | B17: اسم الموديل بالعربي زي ما الناس بتقوله (كورولا). مهم عشان البوت يفهم السؤال بالعربي.
A18: Price_EGP | B18: السعر بالجنيه كرقم. (المستعمل = سعر السوق الحالي).
A19: Body_Type | B19: سيدان / هاتشباك / SUV ... (قائمة).
A20: Sunroof ... Bluetooth_Screen | B20: نعم/لا لأهم الإمكانيات — بتخلي البحث 'عربية بفتحة سقف' فلترة سريعة ودقيقة.
A21: Other_Features | B21: باقي الإمكانيات كنص حر مفصول بفاصلة.
A23: شيت Faults — الأعمدة
A24: Symptom_AR | B24: وصف العطل زي ما المستخدم هيقوله (العربية بتسخن).
A25: Keywords_AR | B25: كلمات وتعبيرات مصرية بديلة ومرادفات مفصولة بفاصلة (سخونة، حرارة، بخار). ده أهم عمود لسرعة ودقة البحث.
A26: Warning_Light | B26: اسم/وصف لمبة التابلوه لو موجودة (للتحليل بالصور).
A27: Possible_Cause / Solution | B27: السبب المحتمل والحل المقترح بجملة واضحة.
A28: Severity / Safe_To_Drive | B28: الخطورة وهل آمن يكمل سواقة؟ البوت بيستخدمهم عشان يحذر المستخدم.
A29: Est_Cost_EGP_Min / Max | B29: تكلفة تقريبية بالجنيه (اختياري).
A30: Applies_To | B30: الكل أو اسم براند/موديل معين لو العطل مرتبط بيه.

Sheet Cars
A1: Car_ID | B1: Brand | C1: Brand_AR | D1: Model | E1: Model_AR | F1: Year | G1: Condition | H1: Price_EGP | I1: Body_Type | J1: Engine_CC | K1: Horsepower | L1: Transmission | M1: Fuel_Type | N1: Fuel_Consumption_L100km | O1: Seats | P1: Sunroof | Q1: Rear_Camera | R1: Cruise_Control | S1: Leather_Seats | T1: Bluetooth_Screen | U1: Other_Features | V1: Notes | W1: Data_Check | X1: Search_Text
A2: C001 | B2: Toyota | C2: =IF(B2="","",IFERROR(INDEX(Lists!$K$2:$K$60,MATCH(B2,Lists!$J$2:$J$60,0)),"")) -> تويوتا | D2: Corolla Active | E2: كورولا أكتيف | F2: 2026 | G2: جديد | H2: 1150000 | I2: سيدان | J2: 1600 | K2: 120 | L2: أوتوماتيك | M2: بنزين | N2: 6.8 | O2: 5 | U2: الفئة الأولى | V2: السعر من خبر أقدم وقد يكون اتغير - راجعه مع الوكيل | W2: =IF(COUNTA(B2:V2)=0,"",IF(OR(B2="",C2="",D2="",F2="",G2="",H2="",I2="",L2="",M2=""),"ناقص",IF(AND(ISNUMBER(F2),ISNUMBER(H2)),"OK","السنة/السعر لازم أرقام"))) -> OK | X2: =IF(B2="","",B2&" "&C2&" "&D2&" "&E2&" "&F2&" "&G2&" "&I2&" "&L2&" "&M2&" سعر "&H2&" جنيه "&U2) -> Toyota تويوتا Corolla Active كورولا أكتيف 2026 جديد سيدان أوتوماتيك بنزين سعر 1150000 جنيه الفئة الأولى
A3: C002 | B3: Toyota | C3: =IF(B3="","",IFERROR(INDEX(Lists!$K$2:$K$60,MATCH(B3,Lists!$J$2:$J$60,0)),"")) -> تويوتا | D3: Corolla Elegance | E3: كورولا إليجانس | F3: 2026 | G3: جديد | H3: 1500000 | I3: سيدان | J3: 1600 | K3: 120 | L3: أوتوماتيك | M3: بنزين | N3: 6.8 | O3: 5 | T3: نعم | U3: شاشة لمس 7 بوصة | V3: السعر من خبر أقدم وقد يكون اتغير - راجعه مع الوكيل | W3: =IF(COUNTA(B3:V3)=0,"",IF(OR(B3="",C3="",D3="",F3="",G3="",H3="",I3="",L3="",M3=""),"ناقص",IF(AND(ISNUMBER(F3),ISNUMBER(H3)),"OK","السنة/السعر لازم أرقام"))) -> OK | X3: =IF(B3="","",B3&" "&C3&" "&D3&" "&E3&" "&F3&" "&G3&" "&I3&" "&L3&" "&M3&" سعر "&H3&" جنيه "&U3) -> Toyota تويوتا Corolla Elegance كورولا إليجانس 2026 جديد سيدان أوتوماتيك بنزين سعر 1500000 جنيه شاشة لمس 7 بوصة
A4: C003 | B4: Toyota | C4: =IF(B4="","",IFERROR(INDEX(Lists!$K$2:$K$60,MATCH(B4,Lists!$J$2:$J$60,0)),"")) -> تويوتا | D4: Corolla Hybrid | E4: كورولا هايبرد | F4: 2026 | G4: جديد | H4: 2000000 | I4: سيدان | J4: 1800 | L4: أوتوماتيك | M4: هايبرد | O4: 5 | U4: محرك هايبرد | V4: السعر من خبر أقدم وقد يكون اتغير - راجعه مع الوكيل | W4: =IF(COUNTA(B4:V4)=0,"",IF(OR(B4="",C4="",D4="",F4="",G4="",H4="",I4="",L4="",M4=""),"ناقص",IF(AND(ISNUMBER(F4),ISNUMBER(H4)),"OK","السنة/السعر لازم أرقام"))) -> OK | X4: =IF(B4="","",B4&" "&C4&" "&D4&" "&E4&" "&F4&" "&G4&" "&I4&" "&L4&" "&M4&" سعر "&H4&" جنيه "&U4) -> Toyota تويوتا Corolla Hybrid كورولا هايبرد 2026 جديد سيدان أوتوماتيك هايبرد سعر 2000000 جنيه محرك هايبرد
A5: C004 | B5: Hyundai | C5: =IF(B5="","",IFERROR(INDEX(Lists!$K$2:$K$60,MATCH(B5,Lists!$J$2:$J$60,0)),"")) -> هيونداي | D5: Elantra AD Entry | E5: إلنترا AD الفئة الأولى | F5: 2026 | G5: جديد | H5: 1035000 | I5: سيدان | J5: 1600 | K5: 128 | L5: أوتوماتيك | M5: بنزين | O5: 5 | U5: مجمعة محليًا | V5: السعر من قائمة أكتوبر 2026 (banker.news) - راجعه مع الوكيل؛ المواصفات الفاضية للاستكمال | W5: =IF(COUNTA(B5:V5)=0,"",IF(OR(B5="",C5="",D5="",F5="",G5="",H5="",I5="",L5="",M5=""),"ناقص",IF(AND(ISNUMBER(F5),ISNUMBER(H5)),"OK","السنة/السعر لازم أرقام"))) -> OK | X5: =IF(B5="","",B5&" "&C5&" "&D5&" "&E5&" "&F5&" "&G5&" "&I5&" "&L5&" "&M5&" سعر "&H5&" جنيه "&U5) -> Hyundai هيونداي Elantra AD Entry إلنترا AD الفئة الأولى 2026 جديد سيدان أوتوماتيك بنزين سعر 1035000 جنيه مجمعة محليًا
A6: C005 | B6: Hyundai | C6: =IF(B6="","",IFERROR(INDEX(Lists!$K$2:$K$60,MATCH(B6,Lists!$J$2:$J$60,0)),"")) -> هيونداي | D6: Elantra AD Top | E6: إلنترا AD الفئة الأعلى | F6: 2026 | G6: جديد | H6: 1250000 | I6: سيدان | J6: 1600 | K6: 128 | L6: أوتوماتيك | M6: بنزين | O6: 5 | U6: مجمعة محليًا | V6: السعر من قائمة أكتوبر 2026 (banker.news) - راجعه مع الوكيل؛ المواصفات الفاضية للاستكمال | W6: =IF(COUNTA(B6:V6)=0,"",IF(OR(B6="",C6="",D6="",F6="",G6="",H6="",I6="",L6="",M6=""),"ناقص",IF(AND(ISNUMBER(F6),ISNUMBER(H6)),"OK","السنة/السعر لازم أرقام"))) -> OK | X6: =IF(B6="","",B6&" "&C6&" "&D6&" "&E6&" "&F6&" "&G6&" "&I6&" "&L6&" "&M6&" سعر "&H6&" جنيه "&U6) -> Hyundai هيونداي Elantra AD Top إلنترا AD الفئة الأعلى 2026 جديد سيدان أوتوماتيك بنزين سعر 1250000 جنيه مجمعة محليًا
A7: C006 | B7: Hyundai | C7: =IF(B7="","",IFERROR(INDEX(Lists!$K$2:$K$60,MATCH(B7,Lists!$J$2:$J$60,0)),"")) -> هيونداي | D7: Venue Blaze | E7: فينيو بليز | F7: 2026 | G7: جديد | H7: 869000 | I7: كروس أوفر | L7: أوتوماتيك | M7: بنزين | O7: 5 | U7: مجمعة محليًا | V7: السعر من قائمة أكتوبر 2026 (banker.news) - راجعه مع الوكيل؛ المواصفات الفاضية للاستكمال | W7: =IF(COUNTA(B7:V7)=0,"",IF(OR(B7="",C7="",D7="",F7="",G7="",H7="",I7="",L7="",M7=""),"ناقص",IF(AND(ISNUMBER(F7),ISNUMBER(H7)),"OK","السنة/السعر لازم أرقام"))) -> OK | X7: =IF(B7="","",B7&" "&C7&" "&D7&" "&E7&" "&F7&" "&G7&" "&I7&" "&L7&" "&M7&" سعر "&H7&" جنيه "&U7) -> Hyundai هيونداي Venue Blaze فينيو بليز 2026 جديد كروس أوفر أوتوماتيك بنزين سعر 869000 جنيه مجمعة محليًا
A8: C007 | B8: Hyundai | C8: =IF(B8="","",IFERROR(INDEX(Lists!$K$2:$K$60,MATCH(B8,Lists!$J$2:$J$60,0)),"")) -> هيونداي | D8: Venue Redline | E8: فينيو ريدلاين | F8: 2026 | G8: جديد | H8: 945000 | I8: كروس أوفر | L8: أوتوماتيك | M8: بنزين | O8: 5 | U8: مجمعة محليًا | V8: السعر من قائمة أكتوبر 2026 (banker.news) - راجعه مع الوكيل؛ المواصفات الفاضية للاستكمال | W8: =IF(COUNTA(B8:V8)=0,"",IF(OR(B8="",C8="",D8="",F8="",G8="",H8="",I8="",L8="",M8=""),"ناقص",IF(AND(ISNUMBER(F8),ISNUMBER(H8)),"OK","السنة/السعر لازم أرقام"))) -> OK | X8: =IF(B8="","",B8&" "&C8&" "&D8&" "&E8&" "&F8&" "&G8&" "&I8&" "&L8&" "&M8&" سعر "&H8&" جنيه "&U8) -> Hyundai هيونداي Venue Redline فينيو ريدلاين 2026 جديد كروس أوفر أوتوماتيك بنزين سعر 945000 جنيه مجمعة محليًا
A9: C008 | B9: Kia | C9: =IF(B9="","",IFERROR(INDEX(Lists!$K$2:$K$60,MATCH(B9,Lists!$J$2:$J$60,0)),"")) -> كيا | D9: Seltos Entry | E9: سيلتوس الفئة الأولى | F9: 2027 | G9: جديد | H9: 1369900 | I9: SUV | L9: أوتوماتيك | M9: بنزين | O9: 5 | U9: موديل 2027 | V9: السعر من قائمة أكتوبر 2026 (banker.news) - راجعه مع الوكيل؛ المواصفات الفاضية للاستكمال | W9: =IF(COUNTA(B9:V9)=0,"",IF(OR(B9="",C9="",D9="",F9="",G9="",H9="",I9="",L9="",M9=""),"ناقص",IF(AND(ISNUMBER(F9),ISNUMBER(H9)),"OK","السنة/السعر لازم أرقام"))) -> OK | X9: =IF(B9="","",B9&" "&C9&" "&D9&" "&E9&" "&F9&" "&G9&" "&I9&" "&L9&" "&M9&" سعر "&H9&" جنيه "&U9) -> Kia كيا Seltos Entry سيلتوس الفئة الأولى 2027 جديد SUV أوتوماتيك بنزين سعر 1369900 جنيه موديل 2027
A10: C009 | B10: Kia | C10: =IF(B10="","",IFERROR(INDEX(Lists!$K$2:$K$60,MATCH(B10,Lists!$J$2:$J$60,0)),"")) -> كيا | D10: Seltos Top | E10: سيلتوس الفئة الأعلى | F10: 2027 | G10: جديد | H10: 1674900 | I10: SUV | L10: أوتوماتيك | M10: بنزين | O10: 5 | U10: موديل 2027 | V10: السعر من قائمة أكتوبر 2026 (banker.news) - راجعه مع الوكيل؛ المواصفات الفاضية للاستكمال | W10: =IF(COUNTA(B10:V10)=0,"",IF(OR(B10="",C10="",D10="",F10="",G10="",H10="",I10="",L10="",M10=""),"ناقص",IF(AND(ISNUMBER(F10),ISNUMBER(H10)),"OK","السنة/السعر لازم أرقام"))) -> OK | X10: =IF(B10="","",B10&" "&C10&" "&D10&" "&E10&" "&F10&" "&G10&" "&I10&" "&L10&" "&M10&" سعر "&H10&" جنيه "&U10) -> Kia كيا Seltos Top سيلتوس الفئة الأعلى 2027 جديد SUV أوتوماتيك بنزين سعر 1674900 جنيه موديل 2027
A11: C010 | B11: Mazda | C11: =IF(B11="","",IFERROR(INDEX(Lists!$K$2:$K$60,MATCH(B11,Lists!$J$2:$J$60,0)),"")) -> مازدا | D11: CX-3 | E11: سي إكس 3 | F11: 2027 | G11: جديد | H11: 1355000 | I11: كروس أوفر | L11: أوتوماتيك | M11: بنزين | O11: 5 | U11: موديل 2027 | V11: السعر من قائمة أكتوبر 2026 (banker.news) - راجعه مع الوكيل؛ المواصفات الفاضية للاستكمال | W11: =IF(COUNTA(B11:V11)=0,"",IF(OR(B11="",C11="",D11="",F11="",G11="",H11="",I11="",L11="",M11=""),"ناقص",IF(AND(ISNUMBER(F11),ISNUMBER(H11)),"OK","السنة/السعر لازم أرقام"))) -> OK | X11: =IF(B11="","",B11&" "&C11&" "&D11&" "&E11&" "&F11&" "&G11&" "&I11&" "&L11&" "&M11&" سعر "&H11&" جنيه "&U11) -> Mazda مازدا CX-3 سي إكس 3 2027 جديد كروس أوفر أوتوماتيك بنزين سعر 1355000 جنيه موديل 2027
A12: C011 | B12: Nissan | C12: =IF(B12="","",IFERROR(INDEX(Lists!$K$2:$K$60,MATCH(B12,Lists!$J$2:$J$60,0)),"")) -> نيسان | D12: Magnite Visia | E12: ماجنيت فيزيا | F12: 2026 | G12: جديد | H12: 819999 | I12: كروس أوفر | J12: 1000 | L12: أوتوماتيك | M12: بنزين | O12: 5 | U12: الفئة الأقل | V12: السعر من قائمة أكتوبر 2026 (banker.news) - راجعه مع الوكيل؛ المواصفات الفاضية للاستكمال | W12: =IF(COUNTA(B12:V12)=0,"",IF(OR(B12="",C12="",D12="",F12="",G12="",H12="",I12="",L12="",M12=""),"ناقص",IF(AND(ISNUMBER(F12),ISNUMBER(H12)),"OK","السنة/السعر لازم أرقام"))) -> OK | X12: =IF(B12="","",B12&" "&C12&" "&D12&" "&E12&" "&F12&" "&G12&" "&I12&" "&L12&" "&M12&" سعر "&H12&" جنيه "&U12) -> Nissan نيسان Magnite Visia ماجنيت فيزيا 2026 جديد كروس أوفر أوتوماتيك بنزين سعر 819999 جنيه الفئة الأقل
A13: C012 | B13: Nissan | C13: =IF(B13="","",IFERROR(INDEX(Lists!$K$2:$K$60,MATCH(B13,Lists!$J$2:$J$60,0)),"")) -> نيسان | D13: Magnite Tekna+ | E13: ماجنيت تيكنا بلس | F13: 2026 | G13: جديد | H13: 899999 | I13: كروس أوفر | J13: 1000 | L13: أوتوماتيك | M13: بنزين | O13: 5 | U13: الفئة الأعلى | V13: السعر من قائمة أكتوبر 2026 (banker.news) - راجعه مع الوكيل؛ المواصفات الفاضية للاستكمال | W13: =IF(COUNTA(B13:V13)=0,"",IF(OR(B13="",C13="",D13="",F13="",G13="",H13="",I13="",L13="",M13=""),"ناقص",IF(AND(ISNUMBER(F13),ISNUMBER(H13)),"OK","السنة/السعر لازم أرقام"))) -> OK | X13: =IF(B13="","",B13&" "&C13&" "&D13&" "&E13&" "&F13&" "&G13&" "&I13&" "&L13&" "&M13&" سعر "&H13&" جنيه "&U13) -> Nissan نيسان Magnite Tekna+ ماجنيت تيكنا بلس 2026 جديد كروس أوفر أوتوماتيك بنزين سعر 899999 جنيه الفئة الأعلى
A14: C013 | B14: Skoda | C14: =IF(B14="","",IFERROR(INDEX(Lists!$K$2:$K$60,MATCH(B14,Lists!$J$2:$J$60,0)),"")) -> سكودا | D14: Octavia Loft | E14: أوكتافيا لوفت | F14: 2027 | G14: جديد | H14: 1825000 | I14: سيدان | J14: 1400 | K14: 150 | L14: DCT | M14: بنزين | O14: 5 | T14: نعم | U14: شاشة 10 بوصة وApple CarPlay، ثبات إلكتروني ESC | V14: السعر من قائمة أكتوبر 2026 (banker.news) - راجعه مع الوكيل؛ المواصفات الفاضية للاستكمال | W14: =IF(COUNTA(B14:V14)=0,"",IF(OR(B14="",C14="",D14="",F14="",G14="",H14="",I14="",L14="",M14=""),"ناقص",IF(AND(ISNUMBER(F14),ISNUMBER(H14)),"OK","السنة/السعر لازم أرقام"))) -> OK | X14: =IF(B14="","",B14&" "&C14&" "&D14&" "&E14&" "&F14&" "&G14&" "&I14&" "&L14&" "&M14&" سعر "&H14&" جنيه "&U14) -> Skoda سكودا Octavia Loft أوكتافيا لوفت 2027 جديد سيدان DCT بنزين سعر 1825000 جنيه شاشة 10 بوصة وApple CarPlay، ثبات إلكتروني ESC
A15: C014 | B15: Skoda | C15: =IF(B15="","",IFERROR(INDEX(Lists!$K$2:$K$60,MATCH(B15,Lists!$J$2:$J$60,0)),"")) -> سكودا | D15: Octavia Suite | E15: أوكتافيا سويت | F15: 2027 | G15: جديد | H15: 2250000 | I15: سيدان | J15: 1400 | K15: 150 | L15: DCT | M15: بنزين | O15: 5 | T15: نعم | U15: شاشة 10 بوصة وApple CarPlay، ثبات إلكتروني ESC | V15: السعر من قائمة أكتوبر 2026 (banker.news) - راجعه مع الوكيل؛ المواصفات الفاضية للاستكمال | W15: =IF(COUNTA(B15:V15)=0,"",IF(OR(B15="",C15="",D15="",F15="",G15="",H15="",I15="",L15="",M15=""),"ناقص",IF(AND(ISNUMBER(F15),ISNUMBER(H15)),"OK","السنة/السعر لازم أرقام"))) -> OK | X15: =IF(B15="","",B15&" "&C15&" "&D15&" "&E15&" "&F15&" "&G15&" "&I15&" "&L15&" "&M15&" سعر "&H15&" جنيه "&U15) -> Skoda سكودا Octavia Suite أوكتافيا سويت 2027 جديد سيدان DCT بنزين سعر 2250000 جنيه شاشة 10 بوصة وApple CarPlay، ثبات إلكتروني ESC
A16: C015 | B16: MG | C16: =IF(B16="","",IFERROR(INDEX(Lists!$K$2:$K$60,MATCH(B16,Lists!$J$2:$J$60,0)),"")) -> إم جي | D16: MG5 Entry | E16: إم جي 5 الفئة الأولى | F16: 2027 | G16: جديد | H16: 890000 | I16: سيدان | L16: أوتوماتيك | M16: بنزين | O16: 5 | V16: السعر من قائمة أكتوبر 2026 (banker.news) - راجعه مع الوكيل؛ المواصفات الفاضية للاستكمال | W16: =IF(COUNTA(B16:V16)=0,"",IF(OR(B16="",C16="",D16="",F16="",G16="",H16="",I16="",L16="",M16=""),"ناقص",IF(AND(ISNUMBER(F16),ISNUMBER(H16)),"OK","السنة/السعر لازم أرقام"))) -> OK | X16: =IF(B16="","",B16&" "&C16&" "&D16&" "&E16&" "&F16&" "&G16&" "&I16&" "&L16&" "&M16&" سعر "&H16&" جنيه "&U16) -> MG إم جي MG5 Entry إم جي 5 الفئة الأولى 2027 جديد سيدان أوتوماتيك بنزين سعر 890000 جنيه
A17: C016 | B17: MG | C17: =IF(B17="","",IFERROR(INDEX(Lists!$K$2:$K$60,MATCH(B17,Lists!$J$2:$J$60,0)),"")) -> إم جي | D17: MG5 Top | E17: إم جي 5 الفئة الأعلى | F17: 2027 | G17: جديد | H17: 990000 | I17: سيدان | L17: أوتوماتيك | M17: بنزين | O17: 5 | V17: السعر من قائمة أكتوبر 2026 (banker.news) - راجعه مع الوكيل؛ المواصفات الفاضية للاستكمال | W17: =IF(COUNTA(B17:V17)=0,"",IF(OR(B17="",C17="",D17="",F17="",G17="",H17="",I17="",L17="",M17=""),"ناقص",IF(AND(ISNUMBER(F17),ISNUMBER(H17)),"OK","السنة/السعر لازم أرقام"))) -> OK | X17: =IF(B17="","",B17&" "&C17&" "&D17&" "&E17&" "&F17&" "&G17&" "&I17&" "&L17&" "&M17&" سعر "&H17&" جنيه "&U17) -> MG إم جي MG5 Top إم جي 5 الفئة الأعلى 2027 جديد سيدان أوتوماتيك بنزين سعر 990000 جنيه
A18: C017 | B18: MG | C18: =IF(B18="","",IFERROR(INDEX(Lists!$K$2:$K$60,MATCH(B18,Lists!$J$2:$J$60,0)),"")) -> إم جي | D18: ZS Plus | E18: زد إس بلس | F18: 2026 | G18: جديد | H18: 1165000 | I18: كروس أوفر | L18: أوتوماتيك | M18: بنزين | O18: 5 | V18: السعر من قائمة أكتوبر 2026 (banker.news) - راجعه مع الوكيل؛ المواصفات الفاضية للاستكمال | W18: =IF(COUNTA(B18:V18)=0,"",IF(OR(B18="",C18="",D18="",F18="",G18="",H18="",I18="",L18="",M18=""),"ناقص",IF(AND(ISNUMBER(F18),ISNUMBER(H18)),"OK","السنة/السعر لازم أرقام"))) -> OK | X18: =IF(B18="","",B18&" "&C18&" "&D18&" "&E18&" "&F18&" "&G18&" "&I18&" "&L18&" "&M18&" سعر "&H18&" جنيه "&U18) -> MG إم جي ZS Plus زد إس بلس 2026 جديد كروس أوفر أوتوماتيك بنزين سعر 1165000 جنيه
A19: C018 | B19: MG | C19: =IF(B19="","",IFERROR(INDEX(Lists!$K$2:$K$60,MATCH(B19,Lists!$J$2:$J$60,0)),"")) -> إم جي | D19: GT | E19: جي تي | F19: 2026 | G19: جديد | H19: 1175000 | I19: سيدان | L19: أوتوماتيك | M19: بنزين | O19: 5 | U19: الفئة الأعلى المتاحة | V19: السعر من قائمة أكتوبر 2026 (banker.news) - راجعه مع الوكيل؛ المواصفات الفاضية للاستكمال | W19: =IF(COUNTA(B19:V19)=0,"",IF(OR(B19="",C19="",D19="",F19="",G19="",H19="",I19="",L19="",M19=""),"ناقص",IF(AND(ISNUMBER(F19),ISNUMBER(H19)),"OK","السنة/السعر لازم أرقام"))) -> OK | X19: =IF(B19="","",B19&" "&C19&" "&D19&" "&E19&" "&F19&" "&G19&" "&I19&" "&L19&" "&M19&" سعر "&H19&" جنيه "&U19) -> MG إم جي GT جي تي 2026 جديد سيدان أوتوماتيك بنزين سعر 1175000 جنيه الفئة الأعلى المتاحة
A20: C019 | B20: MG | C20: =IF(B20="","",IFERROR(INDEX(Lists!$K$2:$K$60,MATCH(B20,Lists!$J$2:$J$60,0)),"")) -> إم جي | D20: G50 Plus | E20: G50 بلس | F20: 2026 | G20: جديد | H20: 1325000 | I20: ميني فان | L20: أوتوماتيك | M20: بنزين | O20: 7 | V20: السعر من قائمة أكتوبر 2026 (banker.news) - راجعه مع الوكيل؛ المواصفات الفاضية للاستكمال | W20: =IF(COUNTA(B20:V20)=0,"",IF(OR(B20="",C20="",D20="",F20="",G20="",H20="",I20="",L20="",M20=""),"ناقص",IF(AND(ISNUMBER(F20),ISNUMBER(H20)),"OK","السنة/السعر لازم أرقام"))) -> OK | X20: =IF(B20="","",B20&" "&C20&" "&D20&" "&E20&" "&F20&" "&G20&" "&I20&" "&L20&" "&M20&" سعر "&H20&" جنيه "&U20) -> MG إم جي G50 Plus G50 بلس 2026 جديد ميني فان أوتوماتيك بنزين سعر 1325000 جنيه
A21: C020 | B21: MG | C21: =IF(B21="","",IFERROR(INDEX(Lists!$K$2:$K$60,MATCH(B21,Lists!$J$2:$J$60,0)),"")) -> إم جي | D21: One | E21: ون | F21: 2026 | G21: جديد | H21: 1425000 | I21: كروس أوفر | L21: أوتوماتيك | M21: بنزين | O21: 5 | V21: السعر من قائمة أكتوبر 2026 (banker.news) - راجعه مع الوكيل؛ المواصفات الفاضية للاستكمال | W21: =IF(COUNTA(B21:V21)=0,"",IF(OR(B21="",C21="",D21="",F21="",G21="",H21="",I21="",L21="",M21=""),"ناقص",IF(AND(ISNUMBER(F21),ISNUMBER(H21)),"OK","السنة/السعر لازم أرقام"))) -> OK | X21: =IF(B21="","",B21&" "&C21&" "&D21&" "&E21&" "&F21&" "&G21&" "&I21&" "&L21&" "&M21&" سعر "&H21&" جنيه "&U21) -> MG إم جي One ون 2026 جديد كروس أوفر أوتوماتيك بنزين سعر 1425000 جنيه
A22: C021 | B22: MG | C22: =IF(B22="","",IFERROR(INDEX(Lists!$K$2:$K$60,MATCH(B22,Lists!$J$2:$J$60,0)),"")) -> إم جي | D22: RX5+ | E22: RX5 بلس | F22: 2027 | G22: جديد | H22: 1475000 | I22: SUV | L22: أوتوماتيك | M22: بنزين | O22: 5 | U22: موديل 2027 | V22: السعر من قائمة أكتوبر 2026 (banker.news) - راجعه مع الوكيل؛ المواصفات الفاضية للاستكمال | W22: =IF(COUNTA(B22:V22)=0,"",IF(OR(B22="",C22="",D22="",F22="",G22="",H22="",I22="",L22="",M22=""),"ناقص",IF(AND(ISNUMBER(F22),ISNUMBER(H22)),"OK","السنة/السعر لازم أرقام"))) -> OK | X22: =IF(B22="","",B22&" "&C22&" "&D22&" "&E22&" "&F22&" "&G22&" "&I22&" "&L22&" "&M22&" سعر "&H22&" جنيه "&U22) -> MG إم جي RX5+ RX5 بلس 2027 جديد SUV أوتوماتيك بنزين سعر 1475000 جنيه موديل 2027
A23: C022 | B23: MG | C23: =IF(B23="","",IFERROR(INDEX(Lists!$K$2:$K$60,MATCH(B23,Lists!$J$2:$J$60,0)),"")) -> إم جي | D23: HS AS33 | E23: HS بنزين | F23: 2027 | G23: جديد | H23: 1575000 | I23: SUV | L23: DCT | M23: بنزين | O23: 5 | U23: موديل 2027 | V23: السعر من قائمة أكتوبر 2026 (banker.news) - راجعه مع الوكيل؛ المواصفات الفاضية للاستكمال | W23: =IF(COUNTA(B23:V23)=0,"",IF(OR(B23="",C23="",D23="",F23="",G23="",H23="",I23="",L23="",M23=""),"ناقص",IF(AND(ISNUMBER(F23),ISNUMBER(H23)),"OK","السنة/السعر لازم أرقام"))) -> OK | X23: =IF(B23="","",B23&" "&C23&" "&D23&" "&E23&" "&F23&" "&G23&" "&I23&" "&L23&" "&M23&" سعر "&H23&" جنيه "&U23) -> MG إم جي HS AS33 HS بنزين 2027 جديد SUV DCT بنزين سعر 1575000 جنيه موديل 2027
A24: C023 | B24: MG | C24: =IF(B24="","",IFERROR(INDEX(Lists!$K$2:$K$60,MATCH(B24,Lists!$J$2:$J$60,0)),"")) -> إم جي | D24: HS HEV | E24: HS هايبرد | F24: 2027 | G24: جديد | H24: 1650000 | I24: SUV | L24: أوتوماتيك | M24: هايبرد | O24: 5 | U24: محرك هايبرد، موديل 2027 | V24: السعر من قائمة أكتوبر 2026 (banker.news) - راجعه مع الوكيل؛ المواصفات الفاضية للاستكمال | W24: =IF(COUNTA(B24:V24)=0,"",IF(OR(B24="",C24="",D24="",F24="",G24="",H24="",I24="",L24="",M24=""),"ناقص",IF(AND(ISNUMBER(F24),ISNUMBER(H24)),"OK","السنة/السعر لازم أرقام"))) -> OK | X24: =IF(B24="","",B24&" "&C24&" "&D24&" "&E24&" "&F24&" "&G24&" "&I24&" "&L24&" "&M24&" سعر "&H24&" جنيه "&U24) -> MG إم جي HS HEV HS هايبرد 2027 جديد SUV أوتوماتيك هايبرد سعر 1650000 جنيه محرك هايبرد، موديل 2027
A25: C024 | B25: MG | C25: =IF(B25="","",IFERROR(INDEX(Lists!$K$2:$K$60,MATCH(B25,Lists!$J$2:$J$60,0)),"")) -> إم جي | D25: 7 Trophy | E25: إم جي 7 تروفي | F25: 2026 | G25: جديد | H25: 1750000 | I25: سيدان | L25: أوتوماتيك | M25: بنزين | O25: 5 | V25: السعر من قائمة أكتوبر 2026 (banker.news) - راجعه مع الوكيل؛ المواصفات الفاضية للاستكمال | W25: =IF(COUNTA(B25:V25)=0,"",IF(OR(B25="",C25="",D25="",F25="",G25="",H25="",I25="",L25="",M25=""),"ناقص",IF(AND(ISNUMBER(F25),ISNUMBER(H25)),"OK","السنة/السعر لازم أرقام"))) -> OK | X25: =IF(B25="","",B25&" "&C25&" "&D25&" "&E25&" "&F25&" "&G25&" "&I25&" "&L25&" "&M25&" سعر "&H25&" جنيه "&U25) -> MG إم جي 7 Trophy إم جي 7 تروفي 2026 جديد سيدان أوتوماتيك بنزين سعر 1750000 جنيه
A26: C025 | B26: MG | C26: =IF(B26="","",IFERROR(INDEX(Lists!$K$2:$K$60,MATCH(B26,Lists!$J$2:$J$60,0)),"")) -> إم جي | D26: RX9 | E26: RX9 | F26: 2026 | G26: جديد | H26: 1960000 | I26: SUV | L26: أوتوماتيك | M26: بنزين | V26: السعر من قائمة أكتوبر 2026 (banker.news) - راجعه مع الوكيل؛ المواصفات الفاضية للاستكمال | W26: =IF(COUNTA(B26:V26)=0,"",IF(OR(B26="",C26="",D26="",F26="",G26="",H26="",I26="",L26="",M26=""),"ناقص",IF(AND(ISNUMBER(F26),ISNUMBER(H26)),"OK","السنة/السعر لازم أرقام"))) -> OK | X26: =IF(B26="","",B26&" "&C26&" "&D26&" "&E26&" "&F26&" "&G26&" "&I26&" "&L26&" "&M26&" سعر "&H26&" جنيه "&U26) -> MG إم جي RX9 RX9 2026 جديد SUV أوتوماتيك بنزين سعر 1960000 جنيه
A27: C026 | B27: Deepal | C27: =IF(B27="","",IFERROR(INDEX(Lists!$K$2:$K$60,MATCH(B27,Lists!$J$2:$J$60,0)),"")) -> ديبال | D27: S05 REEV | E27: S05 مدى ممتد | F27: 2026 | G27: جديد | H27: 1625000 | I27: كروس أوفر | L27: أوتوماتيك | M27: هايبرد | O27: 5 | U27: نسخة المدى الممتد REEV | V27: السعر من قائمة أكتوبر 2026 (banker.news) - راجعه مع الوكيل؛ المواصفات الفاضية للاستكمال | W27: =IF(COUNTA(B27:V27)=0,"",IF(OR(B27="",C27="",D27="",F27="",G27="",H27="",I27="",L27="",M27=""),"ناقص",IF(AND(ISNUMBER(F27),ISNUMBER(H27)),"OK","السنة/السعر لازم أرقام"))) -> OK | X27: =IF(B27="","",B27&" "&C27&" "&D27&" "&E27&" "&F27&" "&G27&" "&I27&" "&L27&" "&M27&" سعر "&H27&" جنيه "&U27) -> Deepal ديبال S05 REEV S05 مدى ممتد 2026 جديد كروس أوفر أوتوماتيك هايبرد سعر 1625000 جنيه نسخة المدى الممتد REEV
A28: C027 | B28: Deepal | C28: =IF(B28="","",IFERROR(INDEX(Lists!$K$2:$K$60,MATCH(B28,Lists!$J$2:$J$60,0)),"")) -> ديبال | D28: S05 BEV | E28: S05 كهرباء | F28: 2026 | G28: جديد | H28: 1775000 | I28: كروس أوفر | J28: 0 | L28: أوتوماتيك | M28: كهرباء | N28: 0 | O28: 5 | U28: كهربائية بالكامل BEV | V28: السعر من قائمة أكتوبر 2026 (banker.news) - راجعه مع الوكيل؛ المواصفات الفاضية للاستكمال | W28: =IF(COUNTA(B28:V28)=0,"",IF(OR(B28="",C28="",D28="",F28="",G28="",H28="",I28="",L28="",M28=""),"ناقص",IF(AND(ISNUMBER(F28),ISNUMBER(H28)),"OK","السنة/السعر لازم أرقام"))) -> OK | X28: =IF(B28="","",B28&" "&C28&" "&D28&" "&E28&" "&F28&" "&G28&" "&I28&" "&L28&" "&M28&" سعر "&H28&" جنيه "&U28) -> Deepal ديبال S05 BEV S05 كهرباء 2026 جديد كروس أوفر أوتوماتيك كهرباء سعر 1775000 جنيه كهربائية بالكامل BEV
A29: C028 | B29: Changan | C29: =IF(B29="","",IFERROR(INDEX(Lists!$K$2:$K$60,MATCH(B29,Lists!$J$2:$J$60,0)),"")) -> شانجان | D29: CS75 Plus Premium | E29: CS75 بلس بريميوم | F29: 2026 | G29: جديد | H29: 1500000 | I29: SUV | L29: أوتوماتيك | M29: بنزين | O29: 5 | V29: السعر من قائمة أكتوبر 2026 (banker.news) - راجعه مع الوكيل؛ المواصفات الفاضية للاستكمال | W29: =IF(COUNTA(B29:V29)=0,"",IF(OR(B29="",C29="",D29="",F29="",G29="",H29="",I29="",L29="",M29=""),"ناقص",IF(AND(ISNUMBER(F29),ISNUMBER(H29)),"OK","السنة/السعر لازم أرقام"))) -> OK | X29: =IF(B29="","",B29&" "&C29&" "&D29&" "&E29&" "&F29&" "&G29&" "&I29&" "&L29&" "&M29&" سعر "&H29&" جنيه "&U29) -> Changan شانجان CS75 Plus Premium CS75 بلس بريميوم 2026 جديد SUV أوتوماتيك بنزين سعر 1500000 جنيه
A30: C029 | B30: Changan | C30: =IF(B30="","",IFERROR(INDEX(Lists!$K$2:$K$60,MATCH(B30,Lists!$J$2:$J$60,0)),"")) -> شانجان | D30: CS75 Plus Flagship | E30: CS75 بلس فلاج شيب | F30: 2026 | G30: جديد | H30: 1650000 | I30: SUV | L30: أوتوماتيك | M30: بنزين | O30: 5 | V30: السعر من قائمة أكتوبر 2026 (banker.news) - راجعه مع الوكيل؛ المواصفات الفاضية للاستكمال | W30: =IF(COUNTA(B30:V30)=0,"",IF(OR(B30="",C30="",D30="",F30="",G30="",H30="",I30="",L30="",M30=""),"ناقص",IF(AND(ISNUMBER(F30),ISNUMBER(H30)),"OK","السنة/السعر لازم أرقام"))) -> OK | X30: =IF(B30="","",B30&" "&C30&" "&D30&" "&E30&" "&F30&" "&G30&" "&I30&" "&L30&" "&M30&" سعر "&H30&" جنيه "&U30) -> Changan شانجان CS75 Plus Flagship CS75 بلس فلاج شيب 2026 جديد SUV أوتوماتيك بنزين سعر 1650000 جنيه
A31: C030 | B31: Changan | C31: =IF(B31="","",IFERROR(INDEX(Lists!$K$2:$K$60,MATCH(B31,Lists!$J$2:$J$60,0)),"")) -> شانجان | D31: CS55 Plus Elite | E31: CS55 بلس إيليت | F31: 2026 | G31: جديد | H31: 1145000 | I31: كروس أوفر | L31: أوتوماتيك | M31: بنزين | O31: 5 | U31: مجمعة محليًا | V31: السعر من قائمة أكتوبر 2026 (banker.news) - راجعه مع الوكيل؛ المواصفات الفاضية للاستكمال | W31: =IF(COUNTA(B31:V31)=0,"",IF(OR(B31="",C31="",D31="",F31="",G31="",H31="",I31="",L31="",M31=""),"ناقص",IF(AND(ISNUMBER(F31),ISNUMBER(H31)),"OK","السنة/السعر لازم أرقام"))) -> OK | X31: =IF(B31="","",B31&" "&C31&" "&D31&" "&E31&" "&F31&" "&G31&" "&I31&" "&L31&" "&M31&" سعر "&H31&" جنيه "&U31) -> Changan شانجان CS55 Plus Elite CS55 بلس إيليت 2026 جديد كروس أوفر أوتوماتيك بنزين سعر 1145000 جنيه مجمعة محليًا
A32: C031 | B32: Changan | C32: =IF(B32="","",IFERROR(INDEX(Lists!$K$2:$K$60,MATCH(B32,Lists!$J$2:$J$60,0)),"")) -> شانجان | D32: CS55 Plus Premium | E32: CS55 بلس بريميوم | F32: 2026 | G32: جديد | H32: 1275000 | I32: كروس أوفر | L32: أوتوماتيك | M32: بنزين | O32: 5 | U32: مجمعة محليًا | V32: السعر من قائمة أكتوبر 2026 (banker.news) - راجعه مع الوكيل؛ المواصفات الفاضية للاستكمال | W32: =IF(COUNTA(B32:V32)=0,"",IF(OR(B32="",C32="",D32="",F32="",G32="",H32="",I32="",L32="",M32=""),"ناقص",IF(AND(ISNUMBER(F32),ISNUMBER(H32)),"OK","السنة/السعر لازم أرقام"))) -> OK | X32: =IF(B32="","",B32&" "&C32&" "&D32&" "&E32&" "&F32&" "&G32&" "&I32&" "&L32&" "&M32&" سعر "&H32&" جنيه "&U32) -> Changan شانجان CS55 Plus Premium CS55 بلس بريميوم 2026 جديد كروس أوفر أوتوماتيك بنزين سعر 1275000 جنيه مجمعة محليًا
A33: C032 | B33: Changan | C33: =IF(B33="","",IFERROR(INDEX(Lists!$K$2:$K$60,MATCH(B33,Lists!$J$2:$J$60,0)),"")) -> شانجان | D33: UNI-V Flagship | E33: يوني في فلاج شيب | F33: 2026 | G33: جديد | H33: 1350000 | I33: سيدان | L33: أوتوماتيك | M33: بنزين | O33: 5 | U33: فئة وحيدة | V33: السعر من قائمة أكتوبر 2026 (banker.news) - راجعه مع الوكيل؛ المواصفات الفاضية للاستكمال | W33: =IF(COUNTA(B33:V33)=0,"",IF(OR(B33="",C33="",D33="",F33="",G33="",H33="",I33="",L33="",M33=""),"ناقص",IF(AND(ISNUMBER(F33),ISNUMBER(H33)),"OK","السنة/السعر لازم أرقام"))) -> OK | X33: =IF(B33="","",B33&" "&C33&" "&D33&" "&E33&" "&F33&" "&G33&" "&I33&" "&L33&" "&M33&" سعر "&H33&" جنيه "&U33) -> Changan شانجان UNI-V Flagship يوني في فلاج شيب 2026 جديد سيدان أوتوماتيك بنزين سعر 1350000 جنيه فئة وحيدة
A34: C033 | B34: Haval | C34: =IF(B34="","",IFERROR(INDEX(Lists!$K$2:$K$60,MATCH(B34,Lists!$J$2:$J$60,0)),"")) -> هافال | D34: H6 Platinum | E34: H6 بلاتينيوم | F34: 2026 | G34: جديد | H34: 1310000 | I34: SUV | L34: DCT | M34: بنزين | O34: 5 | V34: السعر من قائمة أكتوبر 2026 (banker.news) - راجعه مع الوكيل؛ المواصفات الفاضية للاستكمال | W34: =IF(COUNTA(B34:V34)=0,"",IF(OR(B34="",C34="",D34="",F34="",G34="",H34="",I34="",L34="",M34=""),"ناقص",IF(AND(ISNUMBER(F34),ISNUMBER(H34)),"OK","السنة/السعر لازم أرقام"))) -> OK | X34: =IF(B34="","",B34&" "&C34&" "&D34&" "&E34&" "&F34&" "&G34&" "&I34&" "&L34&" "&M34&" سعر "&H34&" جنيه "&U34) -> Haval هافال H6 Platinum H6 بلاتينيوم 2026 جديد SUV DCT بنزين سعر 1310000 جنيه
A35: C034 | B35: Haval | C35: =IF(B35="","",IFERROR(INDEX(Lists!$K$2:$K$60,MATCH(B35,Lists!$J$2:$J$60,0)),"")) -> هافال | D35: H6 Ultra | E35: H6 ألترا | F35: 2026 | G35: جديد | H35: 1500000 | I35: SUV | L35: DCT | M35: بنزين | O35: 5 | V35: السعر من قائمة أكتوبر 2026 (banker.news) - راجعه مع الوكيل؛ المواصفات الفاضية للاستكمال | W35: =IF(COUNTA(B35:V35)=0,"",IF(OR(B35="",C35="",D35="",F35="",G35="",H35="",I35="",L35="",M35=""),"ناقص",IF(AND(ISNUMBER(F35),ISNUMBER(H35)),"OK","السنة/السعر لازم أرقام"))) -> OK | X35: =IF(B35="","",B35&" "&C35&" "&D35&" "&E35&" "&F35&" "&G35&" "&I35&" "&L35&" "&M35&" سعر "&H35&" جنيه "&U35) -> Haval هافال H6 Ultra H6 ألترا 2026 جديد SUV DCT بنزين سعر 1500000 جنيه
A36: C035 | B36: Haval | C36: =IF(B36="","",IFERROR(INDEX(Lists!$K$2:$K$60,MATCH(B36,Lists!$J$2:$J$60,0)),"")) -> هافال | D36: H7 Ultra Black | E36: H7 ألترا بلاك | F36: 2027 | G36: جديد | H36: 1740000 | I36: SUV | L36: أوتوماتيك | M36: هايبرد | O36: 5 | U36: نظام دفع هايبرد | V36: السعر من قائمة أكتوبر 2026 (banker.news) - راجعه مع الوكيل؛ المواصفات الفاضية للاستكمال | W36: =IF(COUNTA(B36:V36)=0,"",IF(OR(B36="",C36="",D36="",F36="",G36="",H36="",I36="",L36="",M36=""),"ناقص",IF(AND(ISNUMBER(F36),ISNUMBER(H36)),"OK","السنة/السعر لازم أرقام"))) -> OK | X36: =IF(B36="","",B36&" "&C36&" "&D36&" "&E36&" "&F36&" "&G36&" "&I36&" "&L36&" "&M36&" سعر "&H36&" جنيه "&U36) -> Haval هافال H7 Ultra Black H7 ألترا بلاك 2027 جديد SUV أوتوماتيك هايبرد سعر 1740000 جنيه نظام دفع هايبرد
A37: C036 | B37: Haval | C37: =IF(B37="","",IFERROR(INDEX(Lists!$K$2:$K$60,MATCH(B37,Lists!$J$2:$J$60,0)),"")) -> هافال | D37: Jolion Standard | E37: جوليان ستاندرد | F37: 2027 | G37: جديد | H37: 1000000 | I37: كروس أوفر | L37: أوتوماتيك | M37: بنزين | O37: 5 | U37: مجمعة محليًا | V37: السعر من قائمة أكتوبر 2026 (banker.news) - راجعه مع الوكيل؛ المواصفات الفاضية للاستكمال | W37: =IF(COUNTA(B37:V37)=0,"",IF(OR(B37="",C37="",D37="",F37="",G37="",H37="",I37="",L37="",M37=""),"ناقص",IF(AND(ISNUMBER(F37),ISNUMBER(H37)),"OK","السنة/السعر لازم أرقام"))) -> OK | X37: =IF(B37="","",B37&" "&C37&" "&D37&" "&E37&" "&F37&" "&G37&" "&I37&" "&L37&" "&M37&" سعر "&H37&" جنيه "&U37) -> Haval هافال Jolion Standard جوليان ستاندرد 2027 جديد كروس أوفر أوتوماتيك بنزين سعر 1000000 جنيه مجمعة محليًا
A38: C037 | B38: Haval | C38: =IF(B38="","",IFERROR(INDEX(Lists!$K$2:$K$60,MATCH(B38,Lists!$J$2:$J$60,0)),"")) -> هافال | D38: Jolion High Deluxe | E38: جوليان هاي ديلوكس | F38: 2027 | G38: جديد | H38: 1155000 | I38: كروس أوفر | L38: أوتوماتيك | M38: بنزين | O38: 5 | U38: مجمعة محليًا | V38: السعر من قائمة أكتوبر 2026 (banker.news) - راجعه مع الوكيل؛ المواصفات الفاضية للاستكمال | W38: =IF(COUNTA(B38:V38)=0,"",IF(OR(B38="",C38="",D38="",F38="",G38="",H38="",I38="",L38="",M38=""),"ناقص",IF(AND(ISNUMBER(F38),ISNUMBER(H38)),"OK","السنة/السعر لازم أرقام"))) -> OK | X38: =IF(B38="","",B38&" "&C38&" "&D38&" "&E38&" "&F38&" "&G38&" "&I38&" "&L38&" "&M38&" سعر "&H38&" جنيه "&U38) -> Haval هافال Jolion High Deluxe جوليان هاي ديلوكس 2027 جديد كروس أوفر أوتوماتيك بنزين سعر 1155000 جنيه مجمعة محليًا
A39: C038 | B39: Chery | C39: =IF(B39="","",IFERROR(INDEX(Lists!$K$2:$K$60,MATCH(B39,Lists!$J$2:$J$60,0)),"")) -> شيري | D39: Arrizo 5 Basic | E39: أريزو 5 بيسك | F39: 2027 | G39: جديد | H39: 690000 | I39: سيدان | L39: أوتوماتيك | M39: بنزين | O39: 5 | U39: أرخص فئة | V39: السعر من قائمة أكتوبر 2026 (banker.news) - راجعه مع الوكيل؛ المواصفات الفاضية للاستكمال | W39: =IF(COUNTA(B39:V39)=0,"",IF(OR(B39="",C39="",D39="",F39="",G39="",H39="",I39="",L39="",M39=""),"ناقص",IF(AND(ISNUMBER(F39),ISNUMBER(H39)),"OK","السنة/السعر لازم أرقام"))) -> OK | X39: =IF(B39="","",B39&" "&C39&" "&D39&" "&E39&" "&F39&" "&G39&" "&I39&" "&L39&" "&M39&" سعر "&H39&" جنيه "&U39) -> Chery شيري Arrizo 5 Basic أريزو 5 بيسك 2027 جديد سيدان أوتوماتيك بنزين سعر 690000 جنيه أرخص فئة
A40: C039 | B40: Chery | C40: =IF(B40="","",IFERROR(INDEX(Lists!$K$2:$K$60,MATCH(B40,Lists!$J$2:$J$60,0)),"")) -> شيري | D40: Arrizo 5 CVT Comfort | E40: أريزو 5 كومفورت | F40: 2027 | G40: جديد | H40: 775000 | I40: سيدان | L40: CVT | M40: بنزين | O40: 5 | V40: السعر من قائمة أكتوبر 2026 (banker.news) - راجعه مع الوكيل؛ المواصفات الفاضية للاستكمال | W40: =IF(COUNTA(B40:V40)=0,"",IF(OR(B40="",C40="",D40="",F40="",G40="",H40="",I40="",L40="",M40=""),"ناقص",IF(AND(ISNUMBER(F40),ISNUMBER(H40)),"OK","السنة/السعر لازم أرقام"))) -> OK | X40: =IF(B40="","",B40&" "&C40&" "&D40&" "&E40&" "&F40&" "&G40&" "&I40&" "&L40&" "&M40&" سعر "&H40&" جنيه "&U40) -> Chery شيري Arrizo 5 CVT Comfort أريزو 5 كومفورت 2027 جديد سيدان CVT بنزين سعر 775000 جنيه
...

Sheet Faults
A1: Fault_ID | B1: Category | C1: Component | D1: Symptom_AR | E1: Keywords_AR | F1: Warning_Light | G1: Possible_Cause | H1: Solution | I1: Severity | J1: Safe_To_Drive | K1: Est_Cost_EGP_Min | L1: Est_Cost_EGP_Max | M1: Applies_To | N1: Notes | O1: Data_Check | P1: Search_Text
A2: F001 | B2: كهرباء | C2: البطارية / السلف | D2: العربية مش بتدور وبسمع طقطقة | E2: مش بتدور، طقطقة، سلف، بطارية، مفيش كهرباء، الكونتاكت | F2: لمبة البطارية | G2: بطارية ضعيفة أو أقطاب مؤكسدة أو عطل في السلف | H2: قياس فولت البطارية وتنظيف الأقطاب وتغيير البطارية، ولو سليمة يتفحص السلف والدينامو | I2: متوسط | J2: لا | K2: 1500 | L2: 6000 | M2: الكل | O2: =IF(COUNTA(B2:N2)=0,"",IF(OR(B2="",C2="",D2="",E2="",G2="",H2="",I2="",J2=""),"ناقص","OK")) -> OK | P2: =IF(D2="","",B2&" "&C2&" "&D2&" "&E2&" "&F2&" "&G2) -> كهرباء البطارية / السلف العربية مش بتدور وبسمع طقطقة مش بتدور، طقطقة، سلف، بطارية، مفيش كهرباء، الكونتاكت لمبة البطارية بطارية ضعيفة أو أقطاب مؤكسدة أو عطل في السلف
A3: F002 | B3: وقود | C3: طلمبة البنزين / الفلتر | D3: المحرك بيدور بس مش بيولع | E3: بيدور ومبيولعش، مش بتولع، طلمبة بنزين، فلتر بنزين، مفيش بنزين | G3: عطل طلمبة البنزين أو فلتر مسدود أو حساس الكرنك أو الكويلات | H3: فحص ضغط البنزين والشرارة وقراءة الأعطال بجهاز الكمبيوتر | I3: متوسط | J3: لا | K3: 800 | L3: 6000 | M3: الكل | O3: =IF(COUNTA(B3:N3)=0,"",IF(OR(B3="",C3="",D3="",E3="",G3="",H3="",I3="",J3=""),"ناقص","OK")) -> OK | P3: =IF(D3="","",B3&" "&C3&" "&D3&" "&E3&" "&F3&" "&G3) -> وقود طلمبة البنزين / الفلتر المحرك بيدور بس مش بيولع بيدور ومبيولعش، مش بتولع، طلمبة بنزين، فلتر بنزين، مفيش بنزين عطل طلمبة البنزين أو فلتر مسدود أو حساس الكرنك أو الكويلات
A4: F003 | B4: محرك | C4: البوجيهات / الكويلات | D4: المحرك بيرتعش وهو واقف | E4: رعشة، هزة، المحرك بيهز، بيرتعش، عدم انتظام، ملل | F4: لمبة المحرك | G4: بوجيهات أو كويلات تالفة أو تسريب هواء أو حساس | H4: تغيير البوجيهات وفحص الكويلات والتروتل | I4: متوسط | J4: بحذر | K4: 600 | L4: 3500 | M4: الكل | O4: =IF(COUNTA(B4:N4)=0,"",IF(OR(B4="",C4="",D4="",E4="",G4="",H4="",I4="",J4=""),"ناقص","OK")) -> OK | P4: =IF(D4="","",B4&" "&C4&" "&D4&" "&E4&" "&F4&" "&G4) -> محرك البوجيهات / الكويلات المحرك بيرتعش وهو واقف رعشة، هزة، المحرك بيهز، بيرتعش، عدم انتظام، ملل لمبة المحرك بوجيهات أو كويلات تالفة أو تسريب هواء أو حساس
A5: F004 | B5: تحذيرات التابلوه | C5: كمبيوتر المحرك | D5: لمبة المحرك (Check Engine) منورة ثابتة | E5: لمبة المحرك، تشيك أنجن، لمبة صفرا، لمبة البرتقاني، Check Engine | F5: لمبة المحرك صفراء | G5: عطل في حساس أو احتراق غير سليم أو غطاء خزان البنزين مش محكم | H5: قراءة كود العطل بجهاز دياجناسيس الأول وبعدها يتحدد العلاج | I5: متوسط | J5: بحذر | K5: 300 | L5: 5000 | M5: الكل | O5: =IF(COUNTA(B5:N5)=0,"",IF(OR(B5="",C5="",D5="",E5="",G5="",H5="",I5="",J5=""),"ناقص","OK")) -> OK | P5: =IF(D5="","",B5&" "&C5&" "&D5&" "&E5&" "&F5&" "&G5) -> تحذيرات التابلوه كمبيوتر المحرك لمبة المحرك (Check Engine) منورة ثابتة لمبة المحرك، تشيك أنجن، لمبة صفرا، لمبة البرتقاني، Check Engine لمبة المحرك صفراء عطل في حساس أو احتراق غير سليم أو غطاء خزان البنزين مش محكم
A6: F005 | B6: تحذيرات التابلوه | C6: الاحتراق / الكتالايزر | D6: لمبة المحرك بتفلش (بتومض) | E6: لمبة بتفلش، لمبة بتنط، لمبة المحرك بتومض، ميس فاير | F6: لمبة المحرك وامضة | G6: احتراق غير مكتمل شديد وممكن يتلف الكتالايزر | H6: وقف العربية وعدم الاستمرار، وفحص البوجيهات والكويلات فورًا | I6: خطير | J6: لا | K6: 1000 | L6: 8000 | M6: الكل | O6: =IF(COUNTA(B6:N6)=0,"",IF(OR(B6="",C6="",D6="",E6="",G6="",H6="",I6="",J6=""),"ناقص","OK")) -> OK | P6: =IF(D6="","",B6&" "&C6&" "&D6&" "&E6&" "&F6&" "&G6) -> تحذيرات التابلوه الاحتراق / الكتالايزر لمبة المحرك بتفلش (بتومض) لمبة بتفلش، لمبة بتنط، لمبة المحرك بتومض، ميس فاير لمبة المحرك وامضة احتراق غير مكتمل شديد وممكن يتلف الكتالايزر
A7: F006 | B7: تحذيرات التابلوه | C7: طلمبة الزيت | D7: لمبة الزيت الحمرا منورة | E7: لمبة الزيت، لمبة حمرا، علبة الزيت، ضغط الزيت، زيت ناقص | F7: لمبة ضغط الزيت | G7: نقص الزيت أو ضعف طلمبة الزيت أو عطل الحساس | H7: وقف المحرك فورًا وفحص مستوى الزيت، ولو الزيت كفاية تتحول لورشة بونش | I7: خطير | J7: لا | K7: 300 | L7: 12000 | M7: الكل | O7: =IF(COUNTA(B7:N7)=0,"",IF(OR(B7="",C7="",D7="",E7="",G7="",H7="",I7="",J7=""),"ناقص","OK")) -> OK | P7: =IF(D7="","",B7&" "&C7&" "&D7&" "&E7&" "&F7&" "&G7) -> تحذيرات التابلوه طلمبة الزيت لمبة الزيت الحمرا منورة لمبة الزيت، لمبة حمرا، علبة الزيت، ضغط الزيت، زيت ناقص لمبة ضغط الزيت نقص الزيت أو ضعف طلمبة الزيت أو عطل الحساس
A8: F007 | B8: محرك | C8: الشنابر / جوانات الصمامات | D8: العربية بتاكل زيت ودخان أزرق من الشكمان | E8: دخان أزرق، بتاكل زيت، زيت بيقل، شنابر، استهلاك زيت | G8: تآكل شنابر أو جوانات صمامات أو تسريب | H8: فحص الكمبريشن وإصلاح التسريب أو تغيير الجوانات | I8: متوسط | J8: بحذر | K8: 2000 | L8: 30000 | M8: الكل | O8: =IF(COUNTA(B8:N8)=0,"",IF(OR(B8="",C8="",D8="",E8="",G8="",H8="",I8="",J8=""),"ناقص","OK")) -> OK | P8: =IF(D8="","",B8&" "&C8&" "&D8&" "&E8&" "&F8&" "&G8) -> محرك الشنابر / جوانات الصمامات العربية بتاكل زيت ودخان أزرق من الشكمان دخان أزرق، بتاكل زيت، زيت بيقل، شنابر، استهلاك زيت تآكل شنابر أو جوانات صمامات أو تسريب
A9: F008 | B9: عادم | C9: حساس الأكسجين / البخاخات | D9: دخان أسود من الشكمان | E9: دخان أسود، عادم أسود، بتحرق بنزين، شكمان أسود | G9: خليط غني بسبب فلتر هواء مسدود أو حساس أكسجين أو بخاخات | H9: تغيير فلتر الهواء وفحص الحساسات والبخاخات | I9: بسيط | J9: نعم | K9: 200 | L9: 3000 | M9: الكل | O9: =IF(COUNTA(B9:N9)=0,"",IF(OR(B9="",C9="",D9="",E9="",G9="",H9="",I9="",J9=""),"ناقص","OK")) -> OK | P9: =IF(D9="","",B9&" "&C9&" "&D9&" "&E9&" "&F9&" "&G9) -> عادم حساس الأكسجين / البخاخات دخان أسود من الشكمان دخان أسود، عادم أسود، بتحرق بنزين، شكمان أسود خليط غني بسبب فلتر هواء مسدود أو حساس أكسجين أو بخاخات
A10: F009 | B10: تبريد | C10: جوان راس السلندر | D10: دخان أبيض كثيف من الشكمان ومياه الردياتير بتقل | E10: دخان أبيض، بخار كتير، مياه الردياتير بتقل، جوان راس | F10: لمبة حرارة المحرك | G10: تسريب مياه التبريد للسلندرات بسبب جوان راس السلندر | H10: وقف المحرك وفحص الكمبريشن وتغيير الجوان وتسوية الراس | I10: خطير | J10: لا | K10: 5000 | L10: 25000 | M10: الكل | O10: =IF(COUNTA(B10:N10)=0,"",IF(OR(B10="",C10="",D10="",E10="",G10="",H10="",I10="",J10=""),"ناقص","OK")) -> OK | P10: =IF(D10="","",B10&" "&C10&" "&D10&" "&E10&" "&F10&" "&G10) -> تبريد جوان راس السلندر دخان أبيض كثيف من الشكمان ومياه الردياتير بتقل دخان أبيض، بخار كتير، مياه الردياتير بتقل، جوان راس لمبة حرارة المحرك تسريب مياه التبريد للسلندرات بسبب جوان راس السلندر
A11: F010 | B11: محرك | C11: الرافعات / الزيت | D11: صوت طقطقة (تكتكة) من المحرك | E11: تكتكة، طقطقة، تاكتك، رافعات، صوت المحرك | G11: زيت قليل أو لزج أو رافعات صمامات متآكلة | H11: فحص مستوى الزيت وتغييره بالنوع الصحيح وبعدها فحص الرافعات | I11: متوسط | J11: بحذر | K11: 300 | L11: 6000 | M11: الكل | O11: =IF(COUNTA(B11:N11)=0,"",IF(OR(B11="",C11="",D11="",E11="",G11="",H11="",I11="",J11=""),"ناقص","OK")) -> OK | P11: =IF(D11="","",B11&" "&C11&" "&D11&" "&E11&" "&F11&" "&G11) -> محرك الرافعات / الزيت صوت طقطقة (تكتكة) من المحرك تكتكة، طقطقة، تاكتك، رافعات، صوت المحرك زيت قليل أو لزج أو رافعات صمامات متآكلة
A12: F011 | B12: محرك | C12: فلتر الهواء / الحساسات | D12: العربية تقيلة ومفيهاش سحب | E12: تقيلة، ضعف سحب، مفيش سحب، مبتجيبش سرعة، بطيئة | G12: فلتر بنزين أو هواء مسدود أو كتالايزر مسدود أو حساس تالف | H12: تغيير الفلاتر وفحص الحساسات والكتالايزر بجهاز الكمبيوتر | I12: متوسط | J12: بحذر | K12: 300 | L12: 6000 | M12: الكل | O12: =IF(COUNTA(B12:N12)=0,"",IF(OR(B12="",C12="",D12="",E12="",G12="",H12="",I12="",J12=""),"ناقص","OK")) -> OK | P12: =IF(D12="","",B12&" "&C12&" "&D12&" "&E12&" "&F12&" "&G12) -> محرك فلتر الهواء / الحساسات العربية تقيلة ومفيهاش سحب تقيلة، ضعف سحب، مفيش سحب، مبتجيبش سرعة، بطيئة فلتر بنزين أو هواء مسدود أو كتالايزر مسدود أو حساس تالف
A13: F012 | B13: وقود | C13: حساس الكرنك / الطلمبة | D13: العربية بتموت فجأة وأنا ماشي | E13: بتموت، بتفصل، بتطفي فجأة، بتقف لوحدها | G13: عطل حساس الكرنك أو طلمبة البنزين أو دينامو أو بطارية | H13: وقف العربية على جنب بأمان وقراءة الأعطال وفحص الطلمبة والدينامو | I13: خطير | J13: لا | K13: 500 | L13: 6000 | M13: الكل | O13: =IF(COUNTA(B13:N13)=0,"",IF(OR(B13="",C13="",D13="",E13="",G13="",H13="",I13="",J13=""),"ناقص","OK")) -> OK | P13: =IF(D13="","",B13&" "&C13&" "&D13&" "&E13&" "&F13&" "&G13) -> وقود حساس الكرنك / الطلمبة العربية بتموت فجأة وأنا ماشي بتموت، بتفصل، بتطفي فجأة، بتقف لوحدها عطل حساس الكرنك أو طلمبة البنزين أو دينامو أو بطارية
A14: F013 | B14: محرك | C14: البوجيهات / البطارية | D14: صعوبة في التشغيل الصبح | E14: صعب تدور الصبح، لازم أحاول كذا مرة، تشغيل على البارد | G14: بوجيهات ضعيفة أو بطارية ضعيفة أو حساس حرارة | H14: تغيير البوجيهات وفحص البطارية وحساس الحرارة | I14: بسيط | J14: نعم | K14: 300 | L14: 3500 | M14: الكل | O14: =IF(COUNTA(B14:N14)=0,"",IF(OR(B14="",C14="",D14="",E14="",G14="",H14="",I14="",J14=""),"ناقص","OK")) -> OK | P14: =IF(D14="","",B14&" "&C14&" "&D14&" "&E14&" "&F14&" "&G14) -> محرك البوجيهات / البطارية صعوبة في التشغيل الصبح صعب تدور الصبح، لازم أحاول كذا مرة، تشغيل على البارد بوجيهات ضعيفة أو بطارية ضعيفة أو حساس حرارة
A15: F014 | B15: تبريد | C15: الردياتير / الثرموستات / المروحة | D15: العربية بتسخن وإبرة الحرارة بتعلى | E15: سخونة، حرارة عالية، بخار من الكبوت، مروحة، مياه الردياتير، العربية بتسخن | F15: لمبة حرارة المحرك حمرا | G15: نقص مياه الردياتير أو عطل الثرموستات أو مروحة التبريد مش شغالة | H15: وقف العربية فورًا وافصل المحرك، استنى يبرد، افحص مستوى المياه، وغير الثرموستات أو المروحة حسب العطل | I15: خطير | J15: لا | K15: 500 | L15: 3000 | M15: الكل | O15: =IF(COUNTA(B15:N15)=0,"",IF(OR(B15="",C15="",D15="",E15="",G15="",H15="",I15="",J15=""),"ناقص","OK")) -> OK | P15: =IF(D15="","",B15&" "&C15&" "&D15&" "&E15&" "&F15&" "&G15) -> تبريد الردياتير / الثرموستات / المروحة العربية بتسخن وإبرة الحرارة بتعلى سخونة، حرارة عالية، بخار من الكبوت، مروحة، مياه الردياتير، العربية بتسخن لمبة حرارة المحرك حمرا نقص مياه الردياتير أو عطل الثرموستات أو مروحة التبريد مش شغالة
A16: F015 | B16: تبريد | C16: الردياتير / الخراطيم | D16: تسريب مياه (أخضر أو وردي) تحت العربية | E16: بتنقط مياه، تسريب ردياتير، سائل أخضر، مياه تبريد، بقعة تحت العربية | F16: لمبة مستوى المياه | G16: تسريب من خرطوم أو الردياتير أو طلمبة المياه | H16: تحديد مكان التسريب وتغيير الخرطوم أو الردياتير أو الطلمبة وتعبئة مياه تبريد | I16: متوسط | J16: بحذر | K16: 300 | L16: 5000 | M16: الكل | O16: =IF(COUNTA(B16:N16)=0,"",IF(OR(B16="",C16="",D16="",E16="",G16="",H16="",I16="",J16=""),"ناقص","OK")) -> OK | P16: =IF(D16="","",B16&" "&C16&" "&D16&" "&E16&" "&F16&" "&G16) -> تبريد الردياتير / الخراطيم تسريب مياه (أخضر أو وردي) تحت العربية بتنقط مياه، تسريب ردياتير، سائل أخضر، مياه تبريد، بقعة تحت العربية لمبة مستوى المياه تسريب من خرطوم أو الردياتير أو طلمبة المياه
A17: F016 | B17: تبريد | C17: مروحة الردياتير | D17: المروحة مش شغالة والعربية بتسخن في الزحمة | E17: مروحة، الفان، سخونة في الزحمة، فان الردياتير | F17: لمبة حرارة المحرك | G17: عطل ريليه المروحة أو موتورها أو حساس الحرارة | H17: فحص الريليه والموتور والحساس وتغيير التالف | I17: متوسط | J17: بحذر | K17: 400 | L17: 3000 | M17: الكل | O17: =IF(COUNTA(B17:N17)=0,"",IF(OR(B17="",C17="",D17="",E17="",G17="",H17="",I17="",J17=""),"ناقص","OK")) -> OK | P17: =IF(D17="","",B17&" "&C17&" "&D17&" "&E17&" "&F17&" "&G17) -> تبريد مروحة الردياتير المروحة مش شغالة والعربية بتسخن في الزحمة مروحة، الفان، سخونة في الزحمة، فان الردياتير لمبة حرارة المحرك عطل ريليه المروحة أو موتورها أو حساس الحرارة
A18: F017 | B18: فرامل | C18: تيل الفرامل | D18: صوت صرير عند الفرملة | E18: صرير، زيزة، صفير فرامل، تيل فرامل، دواسة الفرامل | G18: تآكل تيل الفرامل | H18: فحص وتغيير تيل الفرامل (ويفضل فحص الأسطوانات) | I18: متوسط | J18: بحذر | K18: 600 | L18: 1500 | M18: الكل | O18: =IF(COUNTA(B18:N18)=0,"",IF(OR(B18="",C18="",D18="",E18="",G18="",H18="",I18="",J18=""),"ناقص","OK")) -> OK | P18: =IF(D18="","",B18&" "&C18&" "&D18&" "&E18&" "&F18&" "&G18) -> فرامل تيل الفرامل صوت صرير عند الفرملة صرير، زيزة، صفير فرامل، تيل فرامل، دواسة الفرامل تآكل تيل الفرامل
A19: F018 | B19: فرامل | C19: طلمبة / زيت الفرامل | D19: دواسة الفرامل غاطسة أو طرية | E19: الفرامل بتغطس، دواسة طرية، مفيش فرامل، الفرامل ضعيفة | F19: لمبة الفرامل | G19: هواء في النظام أو تسريب زيت فرامل أو عطل طلمبة الفرامل | H19: وقف العربية وعدم الاستمرار، وفحص التسريب وتغيير زيت الفرامل أو الطلمبة | I19: خطير | J19: لا | K19: 300 | L19: 4000 | M19: الكل | O19: =IF(COUNTA(B19:N19)=0,"",IF(OR(B19="",C19="",D19="",E19="",G19="",H19="",I19="",J19=""),"ناقص","OK")) -> OK | P19: =IF(D19="","",B19&" "&C19&" "&D19&" "&E19&" "&F19&" "&G19) -> فرامل طلمبة / زيت الفرامل دواسة الفرامل غاطسة أو طرية الفرامل بتغطس، دواسة طرية، مفيش فرامل، الفرامل ضعيفة لمبة الفرامل هواء في النظام أو تسريب زيت فرامل أو عطل طلمبة الفرامل
A20: F019 | B20: فرامل | C20: الأقراص (الديسكات) | D20: اهتزاز في الدركسيون عند الفرملة | E20: رعشة فرامل، الدركسيون بيهز، ديسكات، الفرامل بتهز | G20: أقراص الفرامل معوجة بسبب الحرارة | H20: خراطة أو تغيير الأقراص مع التيل | I20: متوسط | J20: بحذر | K20: 800 | L20: 3500 | M20: الكل | O20: =IF(COUNTA(B20:N20)=0,"",IF(OR(B20="",C20="",D20="",E20="",G20="",H20="",I20="",J20=""),"ناقص","OK")) -> OK | P20: =IF(D20="","",B20&" "&C20&" "&D20&" "&E20&" "&F20&" "&G20) -> فرامل الأقراص (الديسكات) اهتزاز في الدركسيون عند الفرملة رعشة فرامل، الدركسيون بيهز، ديسكات، الفرامل بتهز أقراص الفرامل معوجة بسبب الحرارة
A21: F020 | B21: تحذيرات التابلوه | C21: ABS | D21: لمبة ABS منورة | E21: لمبة ABS، لمبة الفرامل، ايه بي اس | F21: لمبة ABS | G21: عطل حساس سرعة العجلة أو وحدة ABS | H21: قراءة الكود وتغيير الحساس التالف (الفرامل العادية بتفضل شغالة) | I21: متوسط | J21: بحذر | K21: 500 | L21: 6000 | M21: الكل | O21: =IF(COUNTA(B21:N21)=0,"",IF(OR(B21="",C21="",D21="",E21="",G21="",H21="",I21="",J21=""),"ناقص","OK")) -> OK | P21: =IF(D21="","",B21&" "&C21&" "&D21&" "&E21&" "&F21&" "&G21) -> تحذيرات التابلوه ABS لمبة ABS منورة لمبة ABS، لمبة الفرامل، ايه بي اس لمبة ABS عطل حساس سرعة العجلة أو وحدة ABS
A22: F021 | B22: فرامل | C22: الكاليبر / التيل | D22: العربية بتشد لجنب لما أفرمل | E22: بتشد يمين، بتشد شمال، بتسحب لجنب، الفرامل | G22: كاليبر مشتبك أو تيل غير متساوي في التآكل | H22: فحص الكاليبرات وتنظيفها أو تغييرها مع التيل | I22: متوسط | J22: بحذر | K22: 600 | L22: 3000 | M22: الكل | O22: =IF(COUNTA(B22:N22)=0,"",IF(OR(B22="",C22="",D22="",E22="",G22="",H22="",I22="",J22=""),"ناقص","OK")) -> OK | P22: =IF(D22="","",B22&" "&C22&" "&D22&" "&E22&" "&F22&" "&G22) -> فرامل الكاليبر / التيل العربية بتشد لجنب لما أفرمل بتشد يمين، بتشد شمال، بتسحب لجنب، الفرامل كاليبر مشتبك أو تيل غير متساوي في التآكل
A23: F022 | B23: فرامل | C23: الكاليبر / التيل | D23: ريحة حريق من الفرامل | E23: ريحة حريق، فرامل سخنت، دخان من العجلة، ريحة شياط | G23: تيل أو كاليبر مشتبك أو استخدام الفرامل بشكل حاد | H23: وقف العربية وتبريد الفرامل وفحص الكاليبر والتيل | I23: متوسط | J23: بحذر | K23: 300 | L23: 3000 | M23: الكل | O23: =IF(COUNTA(B23:N23)=0,"",IF(OR(B23="",C23="",D23="",E23="",G23="",H23="",I23="",J23=""),"ناقص","OK")) -> OK | P23: =IF(D23="","",B23&" "&C23&" "&D23&" "&E23&" "&F23&" "&G23) -> فرامل الكاليبر / التيل ريحة حريق من الفرامل ريحة حريق، فرامل سخنت، دخان من العجلة، ريحة شياط تيل أو كاليبر مشتبك أو استخدام الفرامل بشكل حاد
A24: F023 | B24: كهرباء | C24: الدينامو / البطارية | D24: البطارية بتفضى بسرعة ولمبة البطارية منورة | E24: البطارية بتخلص، مفيش شحن، لمبة البطارية، الدينامو | F24: لمبة البطارية | G24: دينامو ضعيف أو سير الدينامو مفكوك أو سحب كهربائي مستمر | H24: فحص شحن الدينامو والسير وتغيير التالف أو تغيير البطارية | I24: متوسط | J24: بحذر | K24: 1000 | L24: 5000 | M24: الكل | O24: =IF(COUNTA(B24:N24)=0,"",IF(OR(B24="",C24="",D24="",E24="",G24="",H24="",I24="",J24=""),"ناقص","OK")) -> OK | P24: =IF(D24="","",B24&" "&C24&" "&D24&" "&E24&" "&F24&" "&G24) -> كهرباء الدينامو / البطارية البطارية بتفضى بسرعة ولمبة البطارية منورة البطارية بتخلص، مفيش شحن، لمبة البطارية، الدينامو لمبة البطارية دينامو ضعيف أو سير الدينامو مفكوك أو سحب كهربائي مستمر
A25: F024 | B25: كهرباء | C25: اللمبات / الفيوز | D25: الأضوية ضعيفة أو لمبة بتطفي | E25: كشاف، نور ضعيف، لمبة محروقة، فيوز، الأنوار | G25: لمبة محروقة أو فيوز أو وصلة مفكوكة | H25: تغيير اللمبة أو الفيوز وفحص الوصلات | I25: بسيط | J25: بحذر | K25: 50 | L25: 800 | M25: الكل | O25: =IF(COUNTA(B25:N25)=0,"",IF(OR(B25="",C25="",D25="",E25="",G25="",H25="",I25="",J25=""),"ناقص","OK")) -> OK | P25: =IF(D25="","",B25&" "&C25&" "&D25&" "&E25&" "&F25&" "&G25) -> كهرباء اللمبات / الفيوز الأضوية ضعيفة أو لمبة بتطفي كشاف، نور ضعيف، لمبة محروقة، فيوز، الأنوار لمبة محروقة أو فيوز أو وصلة مفكوكة
A26: F025 | B26: كهرباء | C26: الزجاج الكهربائي | D26: الزجاج الكهربائي (الشباك) واقف | E26: الازاز، الشباك، الشباك الكهربا، رافع الزجاج | G26: عطل سويتش أو ريليه أو موتور الزجاج | H26: فحص السويتش والموتور وتغيير التالف | I26: بسيط | J26: نعم | K26: 200 | L26: 1500 | M26: الكل | O26: =IF(COUNTA(B26:N26)=0,"",IF(OR(B26="",C26="",D26="",E26="",G26="",H26="",I26="",J26=""),"ناقص","OK")) -> OK | P26: =IF(D26="","",B26&" "&C26&" "&D26&" "&E26&" "&F26&" "&G26) -> كهرباء الزجاج الكهربائي الزجاج الكهربائي (الشباك) واقف الازاز، الشباك، الشباك الكهربا، رافع الزجاج عطل سويتش أو ريليه أو موتور الزجاج
A27: F026 | B27: كهرباء | C27: الريموت / القفل المركزي | D27: الريموت أو القفل المركزي مش شغال | E27: ريموت، مفتاح، القفل المركزي، بطارية الريموت | G27: بطارية الريموت خلصانة أو موتور القفل تالف | H27: تغيير بطارية الريموت وفحص موتور القفل | I27: بسيط | J27: نعم | K27: 50 | L27: 1500 | M27: الكل | O27: =IF(COUNTA(B27:N27)=0,"",IF(OR(B27="",C27="",D27="",E27="",G27="",H27="",I27="",J27=""),"ناقص","OK")) -> OK | P27: =IF(D27="","",B27&" "&C27&" "&D27&" "&E27&" "&F27&" "&G27) -> كهرباء الريموت / القفل المركزي الريموت أو القفل المركزي مش شغال ريموت، مفتاح، القفل المركزي، بطارية الريموت بطارية الريموت خلصانة أو موتور القفل تالف
A28: F027 | B28: كهرباء | C28: الفيوزات / الأسلاك | D28: فيوز بيحرق باستمرار | E28: فيوز، ماس كهربائي، بيحرق فيوز، ريحة سلك | G28: ماس كهربائي في الأسلاك | H28: فحص الأسلاك وتحديد مكان الماس وإصلاحه فورًا (خطر حريق) | I28: متوسط | J28: بحذر | K28: 300 | L28: 3000 | M28: الكل | O28: =IF(COUNTA(B28:N28)=0,"",IF(OR(B28="",C28="",D28="",E28="",G28="",H28="",I28="",J28=""),"ناقص","OK")) -> OK | P28: =IF(D28="","",B28&" "&C28&" "&D28&" "&E28&" "&F28&" "&G28) -> كهرباء الفيوزات / الأسلاك فيوز بيحرق باستمرار فيوز، ماس كهربائي، بيحرق فيوز، ريحة سلك ماس كهربائي في الأسلاك
A29: F028 | B29: تكييف | C29: الفريون / الكمبروسر | D29: التكييف مش بيبرد | E29: تكييف، مبيبردش، سخن، فريون، مكيف | G29: نقص فريون أو عطل كمبروسر أو كوندنسر مسدود أو فلتر | H29: فحص ضغط الفريون وتعبئته وفحص الكمبروسر والكوندنسر | I29: بسيط | J29: نعم | K29: 400 | L29: 5000 | M29: الكل | O29: =IF(COUNTA(B29:N29)=0,"",IF(OR(B29="",C29="",D29="",E29="",G29="",H29="",I29="",J29=""),"ناقص","OK")) -> OK | P29: =IF(D29="","",B29&" "&C29&" "&D29&" "&E29&" "&F29&" "&G29) -> تكييف الفريون / الكمبروسر التكييف مش بيبرد تكييف، مبيبردش، سخن، فريون، مكيف نقص فريون أو عطل كمبروسر أو كوندنسر مسدود أو فلتر
A30: F029 | B30: تكييف | C30: المبخر / الكلتش | D30: التكييف بيبرد وبعدين يسخن | E30: يبرد ويسخن، التكييف بيقطع، تجمد | G30: تجمد المبخر أو عطل كلتش الكمبروسر أو ريليه | H30: فحص الفريون والكلتش والريليه وتنظيف المبخر | I30: بسيط | J30: نعم | K30: 400 | L30: 4000 | M30: الكل | O30: =IF(COUNTA(B30:N30)=0,"",IF(OR(B30="",C30="",D30="",E30="",G30="",H30="",I30="",J30=""),"ناقص","OK")) -> OK | P30: =IF(D30="","",B30&" "&C30&" "&D30&" "&E30&" "&F30&" "&G30) -> تكييف المبخر / الكلتش التكييف بيبرد وبعدين يسخن يبرد ويسخن، التكييف بيقطع، تجمد تجمد المبخر أو عطل كلتش الكمبروسر أو ريليه
A31: F030 | B31: تكييف | C31: فلتر الكابينة / المبخر | D31: ريحة وحشة من التكييف | E31: ريحة، عفن، رطوبة، ريحة التكييف، بو | G31: فلتر الكابينة قديم أو عفن في المبخر | H31: تغيير فلتر الكابينة وتنظيف المبخر وتعقيمه | I31: بسيط | J31: نعم | K31: 150 | L31: 800 | M31: الكل | O31: =IF(COUNTA(B31:N31)=0,"",IF(OR(B31="",C31="",D31="",E31="",G31="",H31="",I31="",J31=""),"ناقص","OK")) -> OK | P31: =IF(D31="","",B31&" "&C31&" "&D31&" "&E31&" "&F31&" "&G31) -> تكييف فلتر الكابينة / المبخر ريحة وحشة من التكييف ريحة، عفن، رطوبة، ريحة التكييف، بو فلتر الكابينة قديم أو عفن في المبخر
A32: F031 | B32: تكييف | C32: مجرى تصريف المياه | D32: مياه بتنزل جوه العربية من تحت التابلوه | E32: مياه جوه العربية، رطوبة، بلل تحت الكراسي | G32: انسداد مجرى تصريف مياه التكييف | H32: تسليك مجرى التصريف وتنظيف المبخر | I32: بسيط | J32: نعم | K32: 100 | L32: 500 | M32: الكل | O32: =IF(COUNTA(B32:N32)=0,"",IF(OR(B32="",C32="",D32="",E32="",G32="",H32="",I32="",J32=""),"ناقص","OK")) -> OK | P32: =IF(D32="","",B32&" "&C32&" "&D32&" "&E32&" "&F32&" "&G32) -> تكييف مجرى تصريف المياه مياه بتنزل جوه العربية من تحت التابلوه مياه جوه العربية، رطوبة، بلل تحت الكراسي انسداد مجرى تصريف مياه التكييف
A33: F032 | B33: تكييف | C33: الكمبروسر | D33: صوت عالي من التكييف لما أشغله | E33: صوت التكييف، زن، كمبروسر، بلية الكلتش | G33: بلية كمبروسر أو كلتش متآكل | H33: فحص الكمبروسر وتغيير الكلتش أو الكمبروسر | I33: متوسط | J33: نعم | K33: 800 | L33: 8000 | M33: الكل | O33: =IF(COUNTA(B33:N33)=0,"",IF(OR(B33="",C33="",D33="",E33="",G33="",H33="",I33="",J33=""),"ناقص","OK")) -> OK | P33: =IF(D33="","",B33&" "&C33&" "&D33&" "&E33&" "&F33&" "&G33) -> تكييف الكمبروسر صوت عالي من التكييف لما أشغله صوت التكييف، زن، كمبروسر، بلية الكلتش بلية كمبروسر أو كلتش متآكل
A34: F033 | B34: عفشة وتعليق | C34: المساعدين / القصبات | D34: صوت خبط من العفشة على المطبات | E34: خبط، قصبات، مساعدين، كاوتش مساعد، عفشة، المطبات | G34: مساعدين أو قواعد أو قصبات متآكلة | H34: فحص العفشة وتغيير المساعدين أو القواعد أو القصبات التالفة | I34: متوسط | J34: بحذر | K34: 600 | L34: 5000 | M34: الكل | O34: =IF(COUNTA(B34:N34)=0,"",IF(OR(B34="",C34="",D34="",E34="",G34="",H34="",I34="",J34=""),"ناقص","OK")) -> OK | P34: =IF(D34="","",B34&" "&C34&" "&D34&" "&E34&" "&F34&" "&G34) -> عفشة وتعليق المساعدين / القصبات صوت خبط من العفشة على المطبات خبط، قصبات، مساعدين، كاوتش مساعد، عفشة، المطبات مساعدين أو قواعد أو قصبات متآكلة
A35: F034 | B35: إطارات | C35: زوايا العجل | D35: العربية بتشد يمين أو شمال | E35: بتشد، فرمتة، ظبط زوايا، ظبط الدركسيون، بتسحب | G35: زوايا العجل غير مضبوطة أو فرق ضغط الكاوتش | H35: ظبط زوايا العجل وفحص ضغط الكاوتش | I35: بسيط | J35: نعم | K35: 150 | L35: 600 | M35: الكل | O35: =IF(COUNTA(B35:N35)=0,"",IF(OR(B35="",C35="",D35="",E35="",G35="",H35="",I35="",J35=""),"ناقص","OK")) -> OK | P35: =IF(D35="","",B35&" "&C35&" "&D35&" "&E35&" "&F35&" "&G35) -> إطارات زوايا العجل العربية بتشد يمين أو شمال بتشد، فرمتة، ظبط زوايا، ظبط الدركسيون، بتسحب زوايا العجل غير مضبوطة أو فرق ضغط الكاوتش
A36: F035 | B36: إطارات | C36: ميزان الكاوتش | D36: اهتزاز الدركسيون على سرعة 80 إلى 100 | E36: رعشة، زنقة، بالانس، ميزان كاوتش، الدركسيون بيهز | G36: ميزان الكاوتش (البالانس) غير مضبوط أو كاوتش مشوه | H36: ضبط البالانس وفحص الكاوتش والجنوط | I36: بسيط | J36: نعم | K36: 100 | L36: 400 | M36: الكل | O36: =IF(COUNTA(B36:N36)=0,"",IF(OR(B36="",C36="",D36="",E36="",G36="",H36="",I36="",J36=""),"ناقص","OK")) -> OK | P36: =IF(D36="","",B36&" "&C36&" "&D36&" "&E36&" "&F36&" "&G36) -> إطارات ميزان الكاوتش اهتزاز الدركسيون على سرعة 80 إلى 100 رعشة، زنقة، بالانس، ميزان كاوتش، الدركسيون بيهز ميزان الكاوتش (البالانس) غير مضبوط أو كاوتش مشوه
... A44: F043 | B44: عادم | C44: الشكمان / الكاتم | D44: صوت عالي من الشكمان | E44: صوت عادم، شكمان بيزن، كاتم | G44: خرق في الشكمان أو الكاتم | H44: لحام أو تغيير الشكمان أو الكاتم | I44: بسيط | J44: نعم | K44: 300 | L44: 3000 | M44: الكل | O44: =IF(COUNTA(B44:N44)=0,"",IF(OR(B44="",C44="",D44="",E44="",G44="",H44="",I44="",J44=""),"ناقص","OK")) -> OK | P44: =IF(D44="","",B44&" "&C44&" "&D44&" "&E44&" "&F44&" "&G44) -> عادم الشكمان / الكاتم صوت عالي من الشكمان صوت عادم، شكمان بيزن، كاتم خرق في الشكمان أو الكاتم
A45: F044 | B45: عادم | C45: الكتالايزر | D45: ريحة بيض فاسد من الشكمان | E45: ريحة كبريت، ريحة بيض، كتالايزر | F45: لمبة المحرك | G45: تلف الكتالايزر أو خليط غني | H45: فحص الكتالايزر وحساسات الأكسجين وتغييره | I45: متوسط | J45: بحذر | K45: 3000 | L45: 25000 | M45: الكل | O45: =IF(COUNTA(B45:N45)=0,"",IF(OR(B45="",C45="",D45="",E45="",G45="",H45="",I45="",J45=""),"ناقص","OK")) -> OK | P45: =IF(D45="","",B45&" "&C45&" "&D45&" "&E45&" "&F45&" "&G45) -> عادم الكتالايزر ريحة بيض فاسد من الشكمان ريحة كبريت، ريحة بيض، كتالايزر لمبة المحرك تلف الكتالايزر أو خليط غني
A46: F045 | B46: إطارات | C46: الكاوتش | D46: كاوتش بيتآكل من ناحية واحدة | E46: تآكل، كاوتش بيخلص، فرمتة، ناحية واحدة | G46: زوايا غير مضبوطة أو مشكلة في العفشة | H46: ظبط الزوايا وفحص العفشة وتغيير الكاوتش | I46: بسيط | J46: نعم | K46: 150 | L46: 800 | M46: الكل | O46: =IF(COUNTA(B46:N46)=0,"",IF(OR(B46="",C46="",D46="",E46="",G46="",H46="",I46="",J46=""),"ناقص","OK")) -> OK | P46: =IF(D46="","",B46&" "&C46&" "&D46&" "&E46&" "&F46&" "&G46) -> إطارات الكاوتش كاوتش بيتآكل من ناحية واحدة تآكل، كاوتش بيخلص، فرمتة، ناحية واحدة زوايا غير مضبوطة أو مشكلة في العفشة
A47: F046 | B47: إطارات | C47: الكاوتش | D47: كاوتش نايم أو بيفقد هواء | E47: كاوتش نايم، مسمار، بنشر، هواء بيخرج | F47: لمبة ضغط الكاوتش | G47: مسمار أو تسريب من الصمام أو الجنط | H47: استبدال بالاستبن أو إصلاح البنشر وعدم القيادة بكاوتش نايم | I47: متوسط | J47: لا | K47: 50 | L47: 300 | M47: الكل | O47: =IF(COUNTA(B47:N47)=0,"",IF(OR(B47="",C47="",D47="",E47="",G47="",H47="",I47="",J47=""),"ناقص","OK")) -> OK | P47: =IF(D47="","",B47&" "&C47&" "&D47&" "&E47&" "&F47&" "&G47) -> إطارات الكاوتش كاوتش نايم أو بيفقد هواء كاوتش نايم، مسمار، بنشر، هواء بيخرج لمبة ضغط الكاوتش مسمار أو تسريب من الصمام أو الجنط
...

Sheet Lists
A1: Condition | B1: Body_Type | C1: Transmission | D1: Fuel_Type | E1: YesNo | F1: Category | G1: Severity | H1: Safe_To_Drive | J1: Brand | K1: Brand_AR | M1: أضف براند جديد في آخر القائمة (حتى صف 60) وهيظهر تلقائي في القوائم.
A2: جديد | B2: سيدان | C2: أوتوماتيك | D2: بنزين | E2: نعم | F2: محرك | G2: بسيط | H2: نعم | J2: Toyota | K2: تويوتا
A3: مستعمل | B3: هاتشباك | C3: مانيوال | D3: ديزل | E3: لا | F3: فرامل | G3: متوسط | H3: لا | J3: Hyundai | K3: هيونداي
B4: SUV | C4: CVT | D4: هايبرد | F4: كهرباء | G4: خطير | H4: بحذر | J4: Kia | K4: كيا
B5: كروس أوفر | C5: DCT | D5: كهرباء | F5: تكييف | J5: Nissan | K5: نيسان
B6: ميني فان | D6: بنزين/غاز طبيعي | F6: عفشة وتعليق | J6: Chevrolet | K6: شيفروليه
B7: بيك أب | F7: ناقل حركة | J7: Suzuki | K7: سوزوكي
B8: كوبيه | F8: تبريد | J8: Mitsubishi | K8: ميتسوبيشي
B9: فان | F9: عادم | J9: Honda | K9: هوندا
F10: إطارات | J10: Mazda | K10: مازدا
F11: وقود | J11: Renault | K11: رينو
F12: تحذيرات التابلوه | J12: Peugeot | K12: بيجو
F13: أخرى | J13: Fiat | K13: فيات
J14: Skoda | K14: سكودا
J15: Volkswagen | K15: فولكس فاجن
J16: BMW | K16: بي إم دبليو
J17: Mercedes-Benz | K17: مرسيدس
J18: Audi | K18: أودي
J19: Ford | K19: فورد
J20: Opel | K20: أوبل
J21: Chery | K21: شيري
J22: MG | K22: إم جي
J23: BYD | K23: بي واي دي
J24: Geely | K24: جيلي
J25: Haval | K25: هافال
... J32: Jeep | K32: جيب
